nohup: ignoring input
 * Serving Flask app 'erp_api'
 * Debug mode: on
WARNING: This is a development server. Do not use it in a production deployment. Use a production WSGI server instead.
 * Running on all addresses (0.0.0.0)
 * Running on http://127.0.0.1:82
 * Running on http://172.31.9.244:82
Press CTRL+C to quit
 * Restarting with stat
 * Debugger is active!
 * Debugger PIN: 407-091-744
13.233.153.88 - - [04/Dec/2024 07:51:29] "GET /stock_full HTTP/1.1" 200 -
13.233.153.88 - - [04/Dec/2024 07:51:42] "GET /stock_full HTTP/1.1" 200 -
13.233.153.88 - - [04/Dec/2024 09:02:38] "GET /stock_full HTTP/1.1" 200 -
103.35.108.18 - - [04/Dec/2024 09:50:04] "GET /stock_on_replace HTTP/1.1" 200 -
13.233.153.88 - - [04/Dec/2024 09:55:43] "GET /stock_on_replace HTTP/1.1" 200 -
103.35.108.18 - - [04/Dec/2024 09:56:52] "GET /stock_on_replace HTTP/1.1" 200 -
103.35.108.18 - - [04/Dec/2024 09:57:12] "GET /stock_on_risk HTTP/1.1" 200 -
13.233.153.88 - - [04/Dec/2024 09:59:15] "GET /stock_on_risk HTTP/1.1" 200 -
13.233.153.88 - - [04/Dec/2024 10:01:39] "GET /stock_on_risk HTTP/1.1" 200 -
13.233.153.88 - - [04/Dec/2024 10:02:50] "GET /stock_expire HTTP/1.1" 200 -
13.233.153.88 - - [04/Dec/2024 10:03:11] "GET /stock_expire HTTP/1.1" 200 -
13.233.153.88 - - [04/Dec/2024 10:39:26] "GET /stock_full HTTP/1.1" 200 -
127.0.0.1 - - [04/Dec/2024 10:43:50] "GET /conn_php HTTP/1.1" 500 -
Traceback (most recent call last):
  File "/usr/local/lib/python3.10/dist-packages/flask/app.py", line 1536, in __call__
    return self.wsgi_app(environ, start_response)
  File "/usr/local/lib/python3.10/dist-packages/flask/app.py", line 1514, in wsgi_app
    response = self.handle_exception(e)
  File "/usr/local/lib/python3.10/dist-packages/flask/app.py", line 1511, in wsgi_app
    response = self.full_dispatch_request()
  File "/usr/local/lib/python3.10/dist-packages/flask/app.py", line 919, in full_dispatch_request
    rv = self.handle_user_exception(e)
  File "/usr/local/lib/python3.10/dist-packages/flask/app.py", line 917, in full_dispatch_request
    rv = self.dispatch_request()
  File "/usr/local/lib/python3.10/dist-packages/flask/app.py", line 902, in dispatch_request
    return self.ensure_sync(self.view_functions[rule.endpoint])(**view_args)  # type: ignore[no-any-return]
  File "/var/www/html/api/erp_api.py", line 227, in home3
    return jsonify(data)
NameError: name 'data' is not defined
65.49.1.51 - - [04/Dec/2024 10:43:50] "GET / HTTP/1.1" 500 -
Traceback (most recent call last):
  File "/usr/local/lib/python3.10/dist-packages/flask/app.py", line 1536, in __call__
    return self.wsgi_app(environ, start_response)
  File "/usr/local/lib/python3.10/dist-packages/flask/app.py", line 1514, in wsgi_app
    response = self.handle_exception(e)
  File "/usr/local/lib/python3.10/dist-packages/flask/app.py", line 1511, in wsgi_app
    response = self.full_dispatch_request()
  File "/usr/local/lib/python3.10/dist-packages/flask/app.py", line 919, in full_dispatch_request
    rv = self.handle_user_exception(e)
  File "/usr/local/lib/python3.10/dist-packages/flask/app.py", line 917, in full_dispatch_request
    rv = self.dispatch_request()
  File "/usr/local/lib/python3.10/dist-packages/flask/app.py", line 902, in dispatch_request
    return self.ensure_sync(self.view_functions[rule.endpoint])(**view_args)  # type: ignore[no-any-return]
  File "/var/www/html/api/erp_api.py", line 232, in home4
    return jsonify(data)
NameError: name 'data' is not defined
65.49.1.42 - - [04/Dec/2024 10:44:03] "GET /favicon.ico HTTP/1.1" 404 -
127.0.0.1 - - [04/Dec/2024 10:44:06] "GET /conn_php HTTP/1.1" 500 -
65.49.1.50 - - [04/Dec/2024 10:44:06] "GET http://api.ipify.org/?format=json HTTP/1.1Traceback (most recent call last):
  File "/usr/local/lib/python3.10/dist-packages/flask/app.py", line 1536, in __call__
    return self.wsgi_app(environ, start_response)
  File "/usr/local/lib/python3.10/dist-packages/flask/app.py", line 1514, in wsgi_app
    response = self.handle_exception(e)
  File "/usr/local/lib/python3.10/dist-packages/flask/app.py", line 1511, in wsgi_app
    response = self.full_dispatch_request()
  File "/usr/local/lib/python3.10/dist-packages/flask/app.py", line 919, in full_dispatch_request
    rv = self.handle_user_exception(e)
  File "/usr/local/lib/python3.10/dist-packages/flask/app.py", line 917, in full_dispatch_request
    rv = self.dispatch_request()
  File "/usr/local/lib/python3.10/dist-packages/flask/app.py", line 902, in dispatch_request
    return self.ensure_sync(self.view_functions[rule.endpoint])(**view_args)  # type: ignore[no-any-return]
  File "/var/www/html/api/erp_api.py", line 227, in home3
    return jsonify(data)
NameError: name 'data' is not defined
" 500 -
Traceback (most recent call last):
  File "/usr/local/lib/python3.10/dist-packages/flask/app.py", line 1536, in __call__
    return self.wsgi_app(environ, start_response)
  File "/usr/local/lib/python3.10/dist-packages/flask/app.py", line 1514, in wsgi_app
    response = self.handle_exception(e)
  File "/usr/local/lib/python3.10/dist-packages/flask/app.py", line 1511, in wsgi_app
    response = self.full_dispatch_request()
  File "/usr/local/lib/python3.10/dist-packages/flask/app.py", line 919, in full_dispatch_request
    rv = self.handle_user_exception(e)
  File "/usr/local/lib/python3.10/dist-packages/flask/app.py", line 917, in full_dispatch_request
    rv = self.dispatch_request()
  File "/usr/local/lib/python3.10/dist-packages/flask/app.py", line 902, in dispatch_request
    return self.ensure_sync(self.view_functions[rule.endpoint])(**view_args)  # type: ignore[no-any-return]
  File "/var/www/html/api/erp_api.py", line 232, in home4
    return jsonify(data)
NameError: name 'data' is not defined
65.49.1.44 - - [04/Dec/2024 10:44:08] "CONNECT www.shadowserver.org:443 HTTP/1.1" 404 -
13.233.153.88 - - [04/Dec/2024 10:55:53] "GET /stock_full HTTP/1.1" 200 -
13.233.153.88 - - [04/Dec/2024 10:57:57] "GET /stock_sold HTTP/1.1" 200 -
13.233.153.88 - - [04/Dec/2024 11:00:41] "GET /stock_full HTTP/1.1" 200 -
13.233.153.88 - - [04/Dec/2024 11:00:45] "GET /stock_sold HTTP/1.1" 200 -
13.233.153.88 - - [04/Dec/2024 11:01:39] "GET /stock_full HTTP/1.1" 200 -
13.233.153.88 - - [04/Dec/2024 11:35:16] "GET /stock_full HTTP/1.1" 200 -
13.233.153.88 - - [04/Dec/2024 15:13:50] "GET /stock_full HTTP/1.1" 200 -
 * Detected change in '/var/www/html/api/erp_api.py', reloading
 * Restarting with stat
 * Debugger is active!
 * Debugger PIN: 407-091-744
13.233.153.88 - - [04/Dec/2024 15:15:27] "GET /stock_full HTTP/1.1" 200 -
103.72.212.105 - - [04/Dec/2024 16:17:10] "GET /stock_full HTTP/1.1" 200 -
103.72.212.105 - - [04/Dec/2024 16:17:25] "GET /stock_expire HTTP/1.1" 200 -
103.72.212.105 - - [04/Dec/2024 16:17:29] "GET /stock_expire HTTP/1.1" 200 -
103.72.212.105 - - [04/Dec/2024 16:19:06] "GET /stock_sold HTTP/1.1" 200 -
103.72.212.105 - - [04/Dec/2024 16:19:10] "GET /stock_full HTTP/1.1" 200 -
103.72.212.105 - - [04/Dec/2024 16:26:49] "GET /stock_sold HTTP/1.1" 200 -
162.216.150.130 - - [04/Dec/2024 21:34:54] code 400, message Bad request version ('À\x13À')
162.216.150.130 - - [04/Dec/2024 21:34:54] "\x16\x03\x01\x00î\x01\x00\x00ê\x03\x03\x87äø\x92æ$\x0eDl\x11\x9bÌ \x89íKì\x1ckÕáe¾\x1bJ\x1d<8c\x04ÏK >*e¿\x80S¨rÔÎr\x97mÑ¾ÀÞÅ\x92Ã\x1fP\x19\x1c£\x0cÔË÷ÍÊs\x00&À+À/À,À0Ì©Ì¨À\x09À\x13À" HTTPStatus.BAD_REQUEST -
162.216.150.130 - - [04/Dec/2024 21:34:54] code 400, message Bad request version ('À(À$À\x14À')
162.216.150.130 - - [04/Dec/2024 21:34:54] "\x16\x03\x01\x00Ê\x01\x00\x00Æ\x03\x03?\x83è¤\x0c=yöLõ\x98u¢\x00¥>ý¬\x05\x14Ô\x92õÇ\x9c\x8d\x89\x8ciMÊ*\x00\x00hÌ\x14Ì\x13À/À+À0À,À\x11À\x07À'À#À\x13À\x09À(À$À\x14À" HTTPStatus.BAD_REQUEST -
127.0.0.1 - - [04/Dec/2024 23:47:35] "GET /conn_php HTTP/1.1" 500 -
Traceback (most recent call last):
  File "/usr/local/lib/python3.10/dist-packages/flask/app.py", line 1536, in __call__
    return self.wsgi_app(environ, start_response)
  File "/usr/local/lib/python3.10/dist-packages/flask/app.py", line 1514, in wsgi_app
    response = self.handle_exception(e)
  File "/usr/local/lib/python3.10/dist-packages/flask/app.py", line 1511, in wsgi_app
    response = self.full_dispatch_request()
  File "/usr/local/lib/python3.10/dist-packages/flask/app.py", line 919, in full_dispatch_request
    rv = self.handle_user_exception(e)
  File "/usr/local/lib/python3.10/dist-packages/flask/app.py", line 917, in full_dispatch_request
    rv = self.dispatch_request()
  File "/usr/local/lib/python3.10/dist-packages/flask/app.py", line 902, in dispatch_request
    return self.ensure_sync(self.view_functions[rule.endpoint])(**view_args)  # type: ignore[no-any-return]
  File "/var/www/html/api/erp_api.py", line 227, in home3
    return jsonify(data)
NameError: name 'data' is not defined
46.19.138.234 - - [04/Dec/2024 23:47:35] "GET / HTTP/1.1" 500 -
Traceback (most recent call last):
  File "/usr/local/lib/python3.10/dist-packages/flask/app.py", line 1536, in __call__
    return self.wsgi_app(environ, start_response)
  File "/usr/local/lib/python3.10/dist-packages/flask/app.py", line 1514, in wsgi_app
    response = self.handle_exception(e)
  File "/usr/local/lib/python3.10/dist-packages/flask/app.py", line 1511, in wsgi_app
    response = self.full_dispatch_request()
  File "/usr/local/lib/python3.10/dist-packages/flask/app.py", line 919, in full_dispatch_request
    rv = self.handle_user_exception(e)
  File "/usr/local/lib/python3.10/dist-packages/flask/app.py", line 917, in full_dispatch_request
    rv = self.dispatch_request()
  File "/usr/local/lib/python3.10/dist-packages/flask/app.py", line 902, in dispatch_request
    return self.ensure_sync(self.view_functions[rule.endpoint])(**view_args)  # type: ignore[no-any-return]
  File "/var/www/html/api/erp_api.py", line 232, in home4
    return jsonify(data)
NameError: name 'data' is not defined
127.0.0.1 - - [05/Dec/2024 00:31:08] "GET /conn_php HTTP/1.1" 500 -
Traceback (most recent call last):
  File "/usr/local/lib/python3.10/dist-packages/flask/app.py", line 1536, in __call__
    return self.wsgi_app(environ, start_response)
  File "/usr/local/lib/python3.10/dist-packages/flask/app.py", line 1514, in wsgi_app
    response = self.handle_exception(e)
  File "/usr/local/lib/python3.10/dist-packages/flask/app.py", line 1511, in wsgi_app
    response = self.full_dispatch_request()
  File "/usr/local/lib/python3.10/dist-packages/flask/app.py", line 919, in full_dispatch_request
    rv = self.handle_user_exception(e)
  File "/usr/local/lib/python3.10/dist-packages/flask/app.py", line 917, in full_dispatch_request
    rv = self.dispatch_request()
  File "/usr/local/lib/python3.10/dist-packages/flask/app.py", line 902, in dispatch_request
    return self.ensure_sync(self.view_functions[rule.endpoint])(**view_args)  # type: ignore[no-any-return]
  File "/var/www/html/api/erp_api.py", line 227, in home3
    return jsonify(data)
NameError: name 'data' is not defined
51.81.144.44 - - [05/Dec/2024 00:31:08] "GET / HTTP/1.1" 500 -
Traceback (most recent call last):
  File "/usr/local/lib/python3.10/dist-packages/flask/app.py", line 1536, in __call__
    return self.wsgi_app(environ, start_response)
  File "/usr/local/lib/python3.10/dist-packages/flask/app.py", line 1514, in wsgi_app
    response = self.handle_exception(e)
  File "/usr/local/lib/python3.10/dist-packages/flask/app.py", line 1511, in wsgi_app
    response = self.full_dispatch_request()
  File "/usr/local/lib/python3.10/dist-packages/flask/app.py", line 919, in full_dispatch_request
    rv = self.handle_user_exception(e)
  File "/usr/local/lib/python3.10/dist-packages/flask/app.py", line 917, in full_dispatch_request
    rv = self.dispatch_request()
  File "/usr/local/lib/python3.10/dist-packages/flask/app.py", line 902, in dispatch_request
    return self.ensure_sync(self.view_functions[rule.endpoint])(**view_args)  # type: ignore[no-any-return]
  File "/var/www/html/api/erp_api.py", line 232, in home4
    return jsonify(data)
NameError: name 'data' is not defined
15.204.37.27 - - [05/Dec/2024 00:38:08] "GET /favicon.ico HTTP/1.1" 404 -
127.0.0.1 - - [05/Dec/2024 02:48:35] "GET /conn_php HTTP/1.1" 500 -
Traceback (most recent call last):
  File "/usr/local/lib/python3.10/dist-packages/flask/app.py", line 1536, in __call__
    return self.wsgi_app(environ, start_response)
  File "/usr/local/lib/python3.10/dist-packages/flask/app.py", line 1514, in wsgi_app
    response = self.handle_exception(e)
  File "/usr/local/lib/python3.10/dist-packages/flask/app.py", line 1511, in wsgi_app
    response = self.full_dispatch_request()
  File "/usr/local/lib/python3.10/dist-packages/flask/app.py", line 919, in full_dispatch_request
    rv = self.handle_user_exception(e)
  File "/usr/local/lib/python3.10/dist-packages/flask/app.py", line 917, in full_dispatch_request
    rv = self.dispatch_request()
  File "/usr/local/lib/python3.10/dist-packages/flask/app.py", line 902, in dispatch_request
    return self.ensure_sync(self.view_functions[rule.endpoint])(**view_args)  # type: ignore[no-any-return]
  File "/var/www/html/api/erp_api.py", line 227, in home3
    return jsonify(data)
NameError: name 'data' is not defined
95.214.55.43 - - [05/Dec/2024 02:48:35] "GET / HTTP/1.1" 500 -
Traceback (most recent call last):
  File "/usr/local/lib/python3.10/dist-packages/flask/app.py", line 1536, in __call__
    return self.wsgi_app(environ, start_response)
  File "/usr/local/lib/python3.10/dist-packages/flask/app.py", line 1514, in wsgi_app
    response = self.handle_exception(e)
  File "/usr/local/lib/python3.10/dist-packages/flask/app.py", line 1511, in wsgi_app
    response = self.full_dispatch_request()
  File "/usr/local/lib/python3.10/dist-packages/flask/app.py", line 919, in full_dispatch_request
    rv = self.handle_user_exception(e)
  File "/usr/local/lib/python3.10/dist-packages/flask/app.py", line 917, in full_dispatch_request
    rv = self.dispatch_request()
  File "/usr/local/lib/python3.10/dist-packages/flask/app.py", line 902, in dispatch_request
    return self.ensure_sync(self.view_functions[rule.endpoint])(**view_args)  # type: ignore[no-any-return]
  File "/var/www/html/api/erp_api.py", line 232, in home4
    return jsonify(data)
NameError: name 'data' is not defined
127.0.0.1 - - [05/Dec/2024 05:12:40] "GET /conn_php HTTP/1.1" 500 -
67.205.152.191 - - [05/Dec/2024 05:12:40] "Traceback (most recent call last):
  File "/usr/local/lib/python3.10/dist-packages/flask/app.py", line 1536, in __call__
    return self.wsgi_app(environ, start_response)
  File "/usr/local/lib/python3.10/dist-packages/flask/app.py", line 1514, in wsgi_app
    response = self.handle_exception(e)
  File "/usr/local/lib/python3.10/dist-packages/flask/app.py", line 1511, in wsgi_app
    response = self.full_dispatch_request()
  File "/usr/local/lib/python3.10/dist-packages/flask/app.py", line 919, in full_dispatch_request
    rv = self.handle_user_exception(e)
  File "/usr/local/lib/python3.10/dist-packages/flask/app.py", line 917, in full_dispatch_request
    rv = self.dispatch_request()
  File "/usr/local/lib/python3.10/dist-packages/flask/app.py", line 902, in dispatch_request
    return self.ensure_sync(self.view_functions[rule.endpoint])(**view_args)  # type: ignore[no-any-return]
  File "/var/www/html/api/erp_api.py", line 227, in home3
    return jsonify(data)
NameError: name 'data' is not defined
GET / HTTP/1.1" 500 -
Traceback (most recent call last):
  File "/usr/local/lib/python3.10/dist-packages/flask/app.py", line 1536, in __call__
    return self.wsgi_app(environ, start_response)
  File "/usr/local/lib/python3.10/dist-packages/flask/app.py", line 1514, in wsgi_app
    response = self.handle_exception(e)
  File "/usr/local/lib/python3.10/dist-packages/flask/app.py", line 1511, in wsgi_app
    response = self.full_dispatch_request()
  File "/usr/local/lib/python3.10/dist-packages/flask/app.py", line 919, in full_dispatch_request
    rv = self.handle_user_exception(e)
  File "/usr/local/lib/python3.10/dist-packages/flask/app.py", line 917, in full_dispatch_request
    rv = self.dispatch_request()
  File "/usr/local/lib/python3.10/dist-packages/flask/app.py", line 902, in dispatch_request
    return self.ensure_sync(self.view_functions[rule.endpoint])(**view_args)  # type: ignore[no-any-return]
  File "/var/www/html/api/erp_api.py", line 232, in home4
    return jsonify(data)
NameError: name 'data' is not defined
127.0.0.1 - - [05/Dec/2024 07:49:29] "GET /conn_php HTTP/1.1" 500 -
Traceback (most recent call last):
  File "/usr/local/lib/python3.10/dist-packages/flask/app.py", line 1536, in __call__
    return self.wsgi_app(environ, start_response)
  File "/usr/local/lib/python3.10/dist-packages/flask/app.py", line 1514, in wsgi_app
    response = self.handle_exception(e)
  File "/usr/local/lib/python3.10/dist-packages/flask/app.py", line 1511, in wsgi_app
    response = self.full_dispatch_request()
  File "/usr/local/lib/python3.10/dist-packages/flask/app.py", line 919, in full_dispatch_request
    rv = self.handle_user_exception(e)
  File "/usr/local/lib/python3.10/dist-packages/flask/app.py", line 917, in full_dispatch_request
    rv = self.dispatch_request()
  File "/usr/local/lib/python3.10/dist-packages/flask/app.py", line 902, in dispatch_request
    return self.ensure_sync(self.view_functions[rule.endpoint])(**view_args)  # type: ignore[no-any-return]
  File "/var/www/html/api/erp_api.py", line 227, in home3
    return jsonify(data)
NameError: name 'data' is not defined
152.32.206.74 - - [05/Dec/2024 07:49:29] "GET / HTTP/1.1" 500 -
Traceback (most recent call last):
  File "/usr/local/lib/python3.10/dist-packages/flask/app.py", line 1536, in __call__
    return self.wsgi_app(environ, start_response)
  File "/usr/local/lib/python3.10/dist-packages/flask/app.py", line 1514, in wsgi_app
    response = self.handle_exception(e)
  File "/usr/local/lib/python3.10/dist-packages/flask/app.py", line 1511, in wsgi_app
    response = self.full_dispatch_request()
  File "/usr/local/lib/python3.10/dist-packages/flask/app.py", line 919, in full_dispatch_request
    rv = self.handle_user_exception(e)
  File "/usr/local/lib/python3.10/dist-packages/flask/app.py", line 917, in full_dispatch_request
    rv = self.dispatch_request()
  File "/usr/local/lib/python3.10/dist-packages/flask/app.py", line 902, in dispatch_request
    return self.ensure_sync(self.view_functions[rule.endpoint])(**view_args)  # type: ignore[no-any-return]
  File "/var/www/html/api/erp_api.py", line 232, in home4
    return jsonify(data)
NameError: name 'data' is not defined
152.32.206.74 - - [05/Dec/2024 07:49:30] code 400, message Bad request version ('À\x13À')
152.32.206.74 - - [05/Dec/2024 07:49:30] "\x16\x03\x01\x00ò\x01\x00\x00î\x03\x03ÚÓ\x8d\x0b\x88z´L~°\x8f9F3\\á¦¶Q"ãl¨\x99Ä©k¶c@ºJ Üv@\x15¦\x968FMt¿Q¸yT\x1f\x9dSJCÖ\x01Y#ºS0ú\x1b\x02Ó\x9e\x00&À+À/À,À0Ì©Ì¨À\x09À\x13À" HTTPStatus.BAD_REQUEST -
152.32.206.74 - - [05/Dec/2024 07:49:30] code 400, message Bad HTTP/0.9 request type ('t3')
152.32.206.74 - - [05/Dec/2024 07:49:30] "t3 12.1.2" HTTPStatus.BAD_REQUEST -
127.0.0.1 - - [05/Dec/2024 08:40:44] "GET /conn_php HTTP/1.1" 500 -
Traceback (most recent call last):
  File "/usr/local/lib/python3.10/dist-packages/flask/app.py", line 1536, in __call__
    return self.wsgi_app(environ, start_response)
  File "/usr/local/lib/python3.10/dist-packages/flask/app.py", line 1514, in wsgi_app
    response = self.handle_exception(e)
  File "/usr/local/lib/python3.10/dist-packages/flask/app.py", line 1511, in wsgi_app
    response = self.full_dispatch_request()
  File "/usr/local/lib/python3.10/dist-packages/flask/app.py", line 919, in full_dispatch_request
    rv = self.handle_user_exception(e)
  File "/usr/local/lib/python3.10/dist-packages/flask/app.py", line 917, in full_dispatch_request
    rv = self.dispatch_request()
  File "/usr/local/lib/python3.10/dist-packages/flask/app.py", line 902, in dispatch_request
    return self.ensure_sync(self.view_functions[rule.endpoint])(**view_args)  # type: ignore[no-any-return]
  File "/var/www/html/api/erp_api.py", line 227, in home3
    return jsonify(data)
NameError: name 'data' is not defined
46.19.138.234 - - [05/Dec/2024 08:40:44] "GET / HTTP/1.1" 500 -
Traceback (most recent call last):
  File "/usr/local/lib/python3.10/dist-packages/flask/app.py", line 1536, in __call__
    return self.wsgi_app(environ, start_response)
  File "/usr/local/lib/python3.10/dist-packages/flask/app.py", line 1514, in wsgi_app
    response = self.handle_exception(e)
  File "/usr/local/lib/python3.10/dist-packages/flask/app.py", line 1511, in wsgi_app
    response = self.full_dispatch_request()
  File "/usr/local/lib/python3.10/dist-packages/flask/app.py", line 919, in full_dispatch_request
    rv = self.handle_user_exception(e)
  File "/usr/local/lib/python3.10/dist-packages/flask/app.py", line 917, in full_dispatch_request
    rv = self.dispatch_request()
  File "/usr/local/lib/python3.10/dist-packages/flask/app.py", line 902, in dispatch_request
    return self.ensure_sync(self.view_functions[rule.endpoint])(**view_args)  # type: ignore[no-any-return]
  File "/var/www/html/api/erp_api.py", line 232, in home4
    return jsonify(data)
NameError: name 'data' is not defined
127.0.0.1 - - [05/Dec/2024 10:08:02] "GET /conn_php HTTP/1.1" 500 -
Traceback (most recent call last):
  File "/usr/local/lib/python3.10/dist-packages/flask/app.py", line 1536, in __call__
    return self.wsgi_app(environ, start_response)
  File "/usr/local/lib/python3.10/dist-packages/flask/app.py", line 1514, in wsgi_app
    response = self.handle_exception(e)
  File "/usr/local/lib/python3.10/dist-packages/flask/app.py", line 1511, in wsgi_app
    response = self.full_dispatch_request()
  File "/usr/local/lib/python3.10/dist-packages/flask/app.py", line 919, in full_dispatch_request
    rv = self.handle_user_exception(e)
  File "/usr/local/lib/python3.10/dist-packages/flask/app.py", line 917, in full_dispatch_request
    rv = self.dispatch_request()
  File "/usr/local/lib/python3.10/dist-packages/flask/app.py", line 902, in dispatch_request
    return self.ensure_sync(self.view_functions[rule.endpoint])(**view_args)  # type: ignore[no-any-return]
  File "/var/www/html/api/erp_api.py", line 227, in home3
    return jsonify(data)
NameError: name 'data' is not defined
95.214.55.43 - - [05/Dec/2024 10:08:02] "GET / HTTP/1.1" 500 -
Traceback (most recent call last):
  File "/usr/local/lib/python3.10/dist-packages/flask/app.py", line 1536, in __call__
    return self.wsgi_app(environ, start_response)
  File "/usr/local/lib/python3.10/dist-packages/flask/app.py", line 1514, in wsgi_app
    response = self.handle_exception(e)
  File "/usr/local/lib/python3.10/dist-packages/flask/app.py", line 1511, in wsgi_app
    response = self.full_dispatch_request()
  File "/usr/local/lib/python3.10/dist-packages/flask/app.py", line 919, in full_dispatch_request
    rv = self.handle_user_exception(e)
  File "/usr/local/lib/python3.10/dist-packages/flask/app.py", line 917, in full_dispatch_request
    rv = self.dispatch_request()
  File "/usr/local/lib/python3.10/dist-packages/flask/app.py", line 902, in dispatch_request
    return self.ensure_sync(self.view_functions[rule.endpoint])(**view_args)  # type: ignore[no-any-return]
  File "/var/www/html/api/erp_api.py", line 232, in home4
    return jsonify(data)
NameError: name 'data' is not defined
127.0.0.1 - - [05/Dec/2024 10:24:10] "GET /conn_php HTTP/1.1" 500 -
Traceback (most recent call last):
  File "/usr/local/lib/python3.10/dist-packages/flask/app.py", line 1536, in __call__
    return self.wsgi_app(environ, start_response)
  File "/usr/local/lib/python3.10/dist-packages/flask/app.py", line 1514, in wsgi_app
    response = self.handle_exception(e)
  File "/usr/local/lib/python3.10/dist-packages/flask/app.py", line 1511, in wsgi_app
    response = self.full_dispatch_request()
  File "/usr/local/lib/python3.10/dist-packages/flask/app.py", line 919, in full_dispatch_request
    rv = self.handle_user_exception(e)
  File "/usr/local/lib/python3.10/dist-packages/flask/app.py", line 917, in full_dispatch_request
    rv = self.dispatch_request()
  File "/usr/local/lib/python3.10/dist-packages/flask/app.py", line 902, in dispatch_request
    return self.ensure_sync(self.view_functions[rule.endpoint])(**view_args)  # type: ignore[no-any-return]
  File "/var/www/html/api/erp_api.py", line 227, in home3
    return jsonify(data)
NameError: name 'data' is not defined
152.32.247.22 - - [05/Dec/2024 10:24:10] "GET / HTTP/1.1" 500 -
Traceback (most recent call last):
  File "/usr/local/lib/python3.10/dist-packages/flask/app.py", line 1536, in __call__
    return self.wsgi_app(environ, start_response)
  File "/usr/local/lib/python3.10/dist-packages/flask/app.py", line 1514, in wsgi_app
    response = self.handle_exception(e)
  File "/usr/local/lib/python3.10/dist-packages/flask/app.py", line 1511, in wsgi_app
    response = self.full_dispatch_request()
  File "/usr/local/lib/python3.10/dist-packages/flask/app.py", line 919, in full_dispatch_request
    rv = self.handle_user_exception(e)
  File "/usr/local/lib/python3.10/dist-packages/flask/app.py", line 917, in full_dispatch_request
    rv = self.dispatch_request()
  File "/usr/local/lib/python3.10/dist-packages/flask/app.py", line 902, in dispatch_request
    return self.ensure_sync(self.view_functions[rule.endpoint])(**view_args)  # type: ignore[no-any-return]
  File "/var/www/html/api/erp_api.py", line 232, in home4
    return jsonify(data)
NameError: name 'data' is not defined
152.32.247.22 - - [05/Dec/2024 10:24:10] "GET /?__debugger__=yes&cmd=resource&f=console.png HTTP/1.1" 200 -
152.32.247.22 - - [05/Dec/2024 10:24:10] "GET /?__debugger__=yes&cmd=resource&f=debugger.js HTTP/1.1" 200 -
152.32.247.22 - - [05/Dec/2024 10:24:11] "GET /sitemap.xml HTTP/1.1" 404 -
152.32.247.22 - - [05/Dec/2024 10:24:11] "GET /robots.txt HTTP/1.1" 404 -
127.0.0.1 - - [05/Dec/2024 15:23:19] "GET /conn_php HTTP/1.1" 500 -
Traceback (most recent call last):
  File "/usr/local/lib/python3.10/dist-packages/flask/app.py", line 1536, in __call__
    return self.wsgi_app(environ, start_response)
  File "/usr/local/lib/python3.10/dist-packages/flask/app.py", line 1514, in wsgi_app
    response = self.handle_exception(e)
  File "/usr/local/lib/python3.10/dist-packages/flask/app.py", line 1511, in wsgi_app
    response = self.full_dispatch_request()
  File "/usr/local/lib/python3.10/dist-packages/flask/app.py", line 919, in full_dispatch_request
    rv = self.handle_user_exception(e)
  File "/usr/local/lib/python3.10/dist-packages/flask/app.py", line 917, in full_dispatch_request
    rv = self.dispatch_request()
  File "/usr/local/lib/python3.10/dist-packages/flask/app.py", line 902, in dispatch_request
    return self.ensure_sync(self.view_functions[rule.endpoint])(**view_args)  # type: ignore[no-any-return]
  File "/var/www/html/api/erp_api.py", line 227, in home3
    return jsonify(data)
NameError: name 'data' is not defined
46.19.138.234 - - [05/Dec/2024 15:23:19] "GET / HTTP/1.1" 500 -
Traceback (most recent call last):
  File "/usr/local/lib/python3.10/dist-packages/flask/app.py", line 1536, in __call__
    return self.wsgi_app(environ, start_response)
  File "/usr/local/lib/python3.10/dist-packages/flask/app.py", line 1514, in wsgi_app
    response = self.handle_exception(e)
  File "/usr/local/lib/python3.10/dist-packages/flask/app.py", line 1511, in wsgi_app
    response = self.full_dispatch_request()
  File "/usr/local/lib/python3.10/dist-packages/flask/app.py", line 919, in full_dispatch_request
    rv = self.handle_user_exception(e)
  File "/usr/local/lib/python3.10/dist-packages/flask/app.py", line 917, in full_dispatch_request
    rv = self.dispatch_request()
  File "/usr/local/lib/python3.10/dist-packages/flask/app.py", line 902, in dispatch_request
    return self.ensure_sync(self.view_functions[rule.endpoint])(**view_args)  # type: ignore[no-any-return]
  File "/var/www/html/api/erp_api.py", line 232, in home4
    return jsonify(data)
NameError: name 'data' is not defined
127.0.0.1 - - [05/Dec/2024 16:47:38] "GET /conn_php HTTP/1.1" 500 -
Traceback (most recent call last):
  File "/usr/local/lib/python3.10/dist-packages/flask/app.py", line 1536, in __call__
    return self.wsgi_app(environ, start_response)
  File "/usr/local/lib/python3.10/dist-packages/flask/app.py", line 1514, in wsgi_app
    response = self.handle_exception(e)
  File "/usr/local/lib/python3.10/dist-packages/flask/app.py", line 1511, in wsgi_app
    response = self.full_dispatch_request()
  File "/usr/local/lib/python3.10/dist-packages/flask/app.py", line 919, in full_dispatch_request
    rv = self.handle_user_exception(e)
  File "/usr/local/lib/python3.10/dist-packages/flask/app.py", line 917, in full_dispatch_request
    rv = self.dispatch_request()
  File "/usr/local/lib/python3.10/dist-packages/flask/app.py", line 902, in dispatch_request
    return self.ensure_sync(self.view_functions[rule.endpoint])(**view_args)  # type: ignore[no-any-return]
  File "/var/www/html/api/erp_api.py", line 227, in home3
    return jsonify(data)
NameError: name 'data' is not defined
95.214.55.43 - - [05/Dec/2024 16:47:38] "GET / HTTP/1.1" 500 -
Traceback (most recent call last):
  File "/usr/local/lib/python3.10/dist-packages/flask/app.py", line 1536, in __call__
    return self.wsgi_app(environ, start_response)
  File "/usr/local/lib/python3.10/dist-packages/flask/app.py", line 1514, in wsgi_app
    response = self.handle_exception(e)
  File "/usr/local/lib/python3.10/dist-packages/flask/app.py", line 1511, in wsgi_app
    response = self.full_dispatch_request()
  File "/usr/local/lib/python3.10/dist-packages/flask/app.py", line 919, in full_dispatch_request
    rv = self.handle_user_exception(e)
  File "/usr/local/lib/python3.10/dist-packages/flask/app.py", line 917, in full_dispatch_request
    rv = self.dispatch_request()
  File "/usr/local/lib/python3.10/dist-packages/flask/app.py", line 902, in dispatch_request
    return self.ensure_sync(self.view_functions[rule.endpoint])(**view_args)  # type: ignore[no-any-return]
  File "/var/www/html/api/erp_api.py", line 232, in home4
    return jsonify(data)
NameError: name 'data' is not defined
 * Detected change in '/var/www/html/api/erp_api.py', reloading
 * Restarting with stat
 * Debugger is active!
 * Debugger PIN: 407-091-744
